export const catchAsyncErrors = (fn) => {
  return async (req, res, next) => {
    try {
      await fn(req, res, next);
    } catch (err) {
      next(err);
    }
  };
};
